Workbook

Sheet Summary
A1: ME 5309 Mid-Semester - synthetic answer sheets: ground-truth marks (all 60 sheets, batches 1-5)
A2: Total = best three of the four question scores. A struck-out question counts as 0 even if it would have scored higher. Raw = marks for the work on the sheet; Counted = after applying strike-out.
A3: Sr | B3: Roll No. | C3: Name | D3: Archetype / what was done | E3: Answer style | F3: Attempted | G3: Struck out | H3: Q1 raw | I3: Q2 raw | J3: Q3 raw | K3: Q4 raw | L3: Q1 counted | M3: Q2 counted | N3: Q3 counted | O3: Q4 counted | P3: TOTAL /30 (best 3) | Q3: Errors injected (parts) | R3: Spelling typos inserted | S3: Pipeline test focus | T3: PDF file | U3: Batch
A4: Max | H4: 10 | I4: 10 | J4: 10 | K4: 10 | L4: 10 | M4: 10 | N4: 10 | O4: 10 | P4: 30
A5: 1 | B5: ME25M001 | C5: Aarav Sharma | D5: Topper: long, fully-derived answers with assumptions and sanity checks; no deliberate errors | E5: Verbose / long | F5: Q1, Q2, Q3 | G5: None | H5: =SUM(Part_Marks!C5:E5) -> 10 | I5: =SUM(Part_Marks!F5:I5) -> 10 | J5: =SUM(Part_Marks!J5:M5) -> 10 | K5: =SUM(Part_Marks!N5:Q5) -> 0 | L5: =IF(ISNUMBER(SEARCH("Q1",$G5)),0,H5) -> 10 | M5: =IF(ISNUMBER(SEARCH("Q2",$G5)),0,I5) -> 10 | N5: =IF(ISNUMBER(SEARCH("Q3",$G5)),0,J5) -> 10 | O5: =IF(ISNUMBER(SEARCH("Q4",$G5)),0,K5) -> 0 | P5: =LARGE(L5:O5,1)+LARGE(L5:O5,2)+LARGE(L5:O5,3) -> 30 | Q5: =COUNTIFS(Error_Log!$A:$A,$B5,Error_Log!$F:$F,"Error") -> 0 | R5: 6 | S5: Full-marks baseline with very long answers (no false deductions); Q4 not attempted | T5: 02_Answer_Sheets/ME5309_Midsem_S01_Aarav_Sharma.pdf | U5: 1
A6: 2 | B6: ME25M002 | C6: Diya Nair | D6: Strong and concise; uses the acceptable approximation in Q2(c); skips Q1; two minor omissions | E6: Terse / concise | F6: Q2, Q3, Q4 | G6: None | H6: =SUM(Part_Marks!C6:E6) -> 0 | I6: =SUM(Part_Marks!F6:I6) -> 10 | J6: =SUM(Part_Marks!J6:M6) -> 9.5 | K6: =SUM(Part_Marks!N6:Q6) -> 9.5 | L6: =IF(ISNUMBER(SEARCH("Q1",$G6)),0,H6) -> 0 | M6: =IF(ISNUMBER(SEARCH("Q2",$G6)),0,I6) -> 10 | N6: =IF(ISNUMBER(SEARCH("Q3",$G6)),0,J6) -> 9.5 | O6: =IF(ISNUMBER(SEARCH("Q4",$G6)),0,K6) -> 9.5 | P6: =LARGE(L6:O6,1)+LARGE(L6:O6,2)+LARGE(L6:O6,3) -> 29 | Q6: =COUNTIFS(Error_Log!$A:$A,$B6,Error_Log!$F:$F,"Error") -> 2 | R6: 2 | S6: Alternative valid method should get full marks (Q2c); missing verification and weak remedy cost half marks | T6: 02_Answer_Sheets/ME5309_Midsem_S02_Diya_Nair.pdf | U6: 1
A7: 3 | B7: ME25M003 | C7: Rohan Mehta | D7: Average student: several calculation slips and sign/unit mistakes; short answers | E7: Terse / concise | F7: Q1, Q2, Q4 | G7: None | H7: =SUM(Part_Marks!C7:E7) -> 6.5 | I7: =SUM(Part_Marks!F7:I7) -> 5.5 | J7: =SUM(Part_Marks!J7:M7) -> 0 | K7: =SUM(Part_Marks!N7:Q7) -> 7 | L7: =IF(ISNUMBER(SEARCH("Q1",$G7)),0,H7) -> 6.5 | M7: =IF(ISNUMBER(SEARCH("Q2",$G7)),0,I7) -> 5.5 | N7: =IF(ISNUMBER(SEARCH("Q3",$G7)),0,J7) -> 0 | O7: =IF(ISNUMBER(SEARCH("Q4",$G7)),0,K7) -> 7 | P7: =LARGE(L7:O7,1)+LARGE(L7:O7,2)+LARGE(L7:O7,3) -> 19 | Q7: =COUNTIFS(Error_Log!$A:$A,$B7,Error_Log!$F:$F,"Error") -> 10 | R7: 6 | S7: Error-carried-forward credit (Q1a), unit mismatch (Q2c), many partial marks; Q3 not attempted | T7: 02_Answer_Sheets/ME5309_Midsem_S03_Rohan_Mehta.pdf | U7: 1
A8: 4 | B8: ME25M004 | C8: Ananya Iyer | D8: Verbose, attempts all four and strikes out Q3 (which would have scored more than Q1) | E8: Verbose / long | F8: Q1, Q2, Q3, Q4 | G8: Q3 | H8: =SUM(Part_Marks!C8:E8) -> 3.5 | I8: =SUM(Part_Marks!F8:I8) -> 9 | J8: =SUM(Part_Marks!J8:M8) -> 6.5 | K8: =SUM(Part_Marks!N8:Q8) -> 8 | L8: =IF(ISNUMBER(SEARCH("Q1",$G8)),0,H8) -> 3.5 | M8: =IF(ISNUMBER(SEARCH("Q2",$G8)),0,I8) -> 9 | N8: =IF(ISNUMBER(SEARCH("Q3",$G8)),0,J8) -> 0 | O8: =IF(ISNUMBER(SEARCH("Q4",$G8)),0,K8) -> 8 | P8: =LARGE(L8:O8,1)+LARGE(L8:O8,2)+LARGE(L8:O8,3) -> 20.5 | Q8: =COUNTIFS(Error_Log!$A:$A,$B8,Error_Log!$F:$F,"Error") -> 11 | R8: 15 | S8: Strike-out must be honoured: Q3 would have scored 6.5 (> Q1 3.5) but is struck out, so counted = Q1+Q2+Q4 | T8: 02_Answer_Sheets/ME5309_Midsem_S04_Ananya_Iyer.pdf | U8: 1
A9: 5 | B9: ME25M005 | C9: Karthik Subramanian | D9: Bare-answer student: many correct final numbers with no formula or substitution | E9: Terse / concise | F9: Q1, Q3, Q4 | G9: None | H9: =SUM(Part_Marks!C9:E9) -> 3 | I9: =SUM(Part_Marks!F9:I9) -> 0 | J9: =SUM(Part_Marks!J9:M9) -> 4 | K9: =SUM(Part_Marks!N9:Q9) -> 2 | L9: =IF(ISNUMBER(SEARCH("Q1",$G9)),0,H9) -> 3 | M9: =IF(ISNUMBER(SEARCH("Q2",$G9)),0,I9) -> 0 | N9: =IF(ISNUMBER(SEARCH("Q3",$G9)),0,J9) -> 4 | O9: =IF(ISNUMBER(SEARCH("Q4",$G9)),0,K9) -> 2 | P9: =LARGE(L9:O9,1)+LARGE(L9:O9,2)+LARGE(L9:O9,3) -> 9 | Q9: =COUNTIFS(Error_Log!$A:$A,$B9,Error_Log!$F:$F,"Error") -> 7 | R9: 7 | S9: Instruction 5: answers without formula/substitution earn no credit even if numerically correct | T9: 02_Answer_Sheets/ME5309_Midsem_S05_Karthik_Subramanian.pdf | U9: 1
A10: 6 | B10: ME25M006 | C10: Meera Krishnan | D10: Chatty and wordy; attempts all four without striking out (best three must be picked) | E10: Verbose / long | F10: Q1, Q2, Q3, Q4 | G10: None | H10: =SUM(Part_Marks!C10:E10) -> 10 | I10: =SUM(Part_Marks!F10:I10) -> 8 | J10: =SUM(Part_Marks!J10:M10) -> 9 | K10: =SUM(Part_Marks!N10:Q10) -> 7.5 | L10: =IF(ISNUMBER(SEARCH("Q1",$G10)),0,H10) -> 10 | M10: =IF(ISNUMBER(SEARCH("Q2",$G10)),0,I10) -> 8 | N10: =IF(ISNUMBER(SEARCH("Q3",$G10)),0,J10) -> 9 | O10: =IF(ISNUMBER(SEARCH("Q4",$G10)),0,K10) -> 7.5 | P10: =LARGE(L10:O10,1)+LARGE(L10:O10,2)+LARGE(L10:O10,3) -> 27 | Q10: =COUNTIFS(Error_Log!$A:$A,$B10,Error_Log!$F:$F,"Error") -> 6 | R10: 19 | S10: Best-3 selection: Q4 (7.5) is the lowest and must be dropped; chatty filler text should not confuse grading | T10: 02_Answer_Sheets/ME5309_Midsem_S06_Meera_Krishnan.pdf | U10: 1
A11: 7 | B11: ME25M007 | C11: Vikram Patel | D11: Weak: conceptual misunderstandings in Q2, Q3 and Q4; short answers | E11: Terse / concise | F11: Q2, Q3, Q4 | G11: None | H11: =SUM(Part_Marks!C11:E11) -> 0 | I11: =SUM(Part_Marks!F11:I11) -> 3.5 | J11: =SUM(Part_Marks!J11:M11) -> 2 | K11: =SUM(Part_Marks!N11:Q11) -> 2.5 | L11: =IF(ISNUMBER(SEARCH("Q1",$G11)),0,H11) -> 0 | M11: =IF(ISNUMBER(SEARCH("Q2",$G11)),0,I11) -> 3.5 | N11: =IF(ISNUMBER(SEARCH("Q3",$G11)),0,J11) -> 2 | O11: =IF(ISNUMBER(SEARCH("Q4",$G11)),0,K11) -> 2.5 | P11: =LARGE(L11:O11,1)+LARGE(L11:O11,2)+LARGE(L11:O11,3) -> 8 | Q11: =COUNTIFS(Error_Log!$A:$A,$B11,Error_Log!$F:$F,"Error") -> 12 | R11: 13 | S11: Low-score case with conceptual errors in every question; checks that partial marks are small but non-zero | T11: 02_Answer_Sheets/ME5309_Midsem_S07_Vikram_Patel.pdf | U11: 1
A12: 8 | B12: ME25M008 | C12: Sneha Reddy | D12: Good but ran out of time: attempted only two questions (Q2 and Q3 blank) | E12: Verbose / long | F12: Q1, Q4 | G12: None | H12: =SUM(Part_Marks!C12:E12) -> 9 | I12: =SUM(Part_Marks!F12:I12) -> 0 | J12: =SUM(Part_Marks!J12:M12) -> 0 | K12: =SUM(Part_Marks!N12:Q12) -> 8.5 | L12: =IF(ISNUMBER(SEARCH("Q1",$G12)),0,H12) -> 9 | M12: =IF(ISNUMBER(SEARCH("Q2",$G12)),0,I12) -> 0 | N12: =IF(ISNUMBER(SEARCH("Q3",$G12)),0,J12) -> 0 | O12: =IF(ISNUMBER(SEARCH("Q4",$G12)),0,K12) -> 8.5 | P12: =LARGE(L12:O12,1)+LARGE(L12:O12,2)+LARGE(L12:O12,3) -> 17.5 | Q12: =COUNTIFS(Error_Log!$A:$A,$B12,Error_Log!$F:$F,"Error") -> 3 | R12: 7 | S12: Only two questions attempted: the third counted question must score 0 (total out of 30 = 17.5) | T12: 02_Answer_Sheets/ME5309_Midsem_S08_Sneha_Reddy.pdf | U12: 1
A13: 9 | B13: ME25M009 | C13: Arjun Das | D13: Mixed style (some parts long, some one-liners); partial credit in every part attempted | E13: Mixed (long and short parts) | F13: Q1, Q2, Q3 | G13: None | H13: =SUM(Part_Marks!C13:E13) -> 8 | I13: =SUM(Part_Marks!F13:I13) -> 6.5 | J13: =SUM(Part_Marks!J13:M13) -> 6 | K13: =SUM(Part_Marks!N13:Q13) -> 0 | L13: =IF(ISNUMBER(SEARCH("Q1",$G13)),0,H13) -> 8 | M13: =IF(ISNUMBER(SEARCH("Q2",$G13)),0,I13) -> 6.5 | N13: =IF(ISNUMBER(SEARCH("Q3",$G13)),0,J13) -> 6 | O13: =IF(ISNUMBER(SEARCH("Q4",$G13)),0,K13) -> 0 | P13: =LARGE(L13:O13,1)+LARGE(L13:O13,2)+LARGE(L13:O13,3) -> 20.5 | Q13: =COUNTIFS(Error_Log!$A:$A,$B13,Error_Log!$F:$F,"Error") -> 7 | R13: 9 | S13: Partial marking across almost every part; varied length within one script | T13: 02_Answer_Sheets/ME5309_Midsem_S09_Arjun_Das.pdf | U13: 1
A14: 10 | B14: ME25M010 | C14: Priya Venkatesh | D14: Near-perfect and verbose; attempts all four (Q3 is the dropped question) | E14: Verbose / long | F14: Q1, Q2, Q3, Q4 | G14: None | H14: =SUM(Part_Marks!C14:E14) -> 9.5 | I14: =SUM(Part_Marks!F14:I14) -> 10 | J14: =SUM(Part_Marks!J14:M14) -> 9 | K14: =SUM(Part_Marks!N14:Q14) -> 10 | L14: =IF(ISNUMBER(SEARCH("Q1",$G14)),0,H14) -> 9.5 | M14: =IF(ISNUMBER(SEARCH("Q2",$G14)),0,I14) -> 10 | N14: =IF(ISNUMBER(SEARCH("Q3",$G14)),0,J14) -> 9 | O14: =IF(ISNUMBER(SEARCH("Q4",$G14)),0,K14) -> 10 | P14: =LARGE(L14:O14,1)+LARGE(L14:O14,2)+LARGE(L14:O14,3) -> 29.5 | Q14: =COUNTIFS(Error_Log!$A:$A,$B14,Error_Log!$F:$F,"Error") -> 2 | R14: 3 | S14: Best three of four: Q2 (10) + Q4 (10) + Q1 (9.5) = 29.5; Q3 (9.0) dropped | T14: 02_Answer_Sheets/ME5309_Midsem_S10_Priya_Venkatesh.pdf | U14: 1
A15: 11 | B15: ME25M011 | C15: Rahul Gupta | D15: Careless with units and significant figures; otherwise average | E15: Terse / concise | F15: Q1, Q3, Q4 | G15: None | H15: =SUM(Part_Marks!C15:E15) -> 9 | I15: =SUM(Part_Marks!F15:I15) -> 0 | J15: =SUM(Part_Marks!J15:M15) -> 6.5 | K15: =SUM(Part_Marks!N15:Q15) -> 6.5 | L15: =IF(ISNUMBER(SEARCH("Q1",$G15)),0,H15) -> 9 | M15: =IF(ISNUMBER(SEARCH("Q2",$G15)),0,I15) -> 0 | N15: =IF(ISNUMBER(SEARCH("Q3",$G15)),0,J15) -> 6.5 | O15: =IF(ISNUMBER(SEARCH("Q4",$G15)),0,K15) -> 6.5 | P15: =LARGE(L15:O15,1)+LARGE(L15:O15,2)+LARGE(L15:O15,3) -> 22 | Q15: =COUNTIFS(Error_Log!$A:$A,$B15,Error_Log!$F:$F,"Error") -> 9 | R15: 6 | S15: Instruction 6/7 penalties: missing unit and fewer than 3 significant figures (0.5 each) | T15: 02_Answer_Sheets/ME5309_Midsem_S11_Rahul_Gupta.pdf | U15: 1
A16: 12 | B16: ME25M012 | C16: Ishita Banerjee | D16: Thoughtful and verbose derivations; correct conclusions with weak justification in a few places | E16: Verbose / long | F16: Q2, Q3, Q4 | G16: None | H16: =SUM(Part_Marks!C16:E16) -> 0 | I16: =SUM(Part_Marks!F16:I16) -> 9.5 | J16: =SUM(Part_Marks!J16:M16) -> 9 | K16: =SUM(Part_Marks!N16:Q16) -> 9 | L16: =IF(ISNUMBER(SEARCH("Q1",$G16)),0,H16) -> 0 | M16: =IF(ISNUMBER(SEARCH("Q2",$G16)),0,I16) -> 9.5 | N16: =IF(ISNUMBER(SEARCH("Q3",$G16)),0,J16) -> 9 | O16: =IF(ISNUMBER(SEARCH("Q4",$G16)),0,K16) -> 9 | P16: =LARGE(L16:O16,1)+LARGE(L16:O16,2)+LARGE(L16:O16,3) -> 27.5 | Q16: =COUNTIFS(Error_Log!$A:$A,$B16,Error_Log!$F:$F,"Error") -> 3 | R16: 10 | S16: Right conclusions with wrong reasoning (Q2d) should get partial credit; small arithmetic slip in Q3c | T16: 02_Answer_Sheets/ME5309_Midsem_S12_Ishita_Banerjee.pdf | U16: 1
... A64: 60 | B64: ME25M060 | C64: Ankita Sinha | D64: Attempted all four, no strike-out (best three must be picked) | E64: Verbose / long | F64: Q1, Q2, Q3, Q4 | G64: None | H64: =SUM(Part_Marks!C64:E64) -> 8 | I64: =SUM(Part_Marks!F64:I64) -> 8.5 | J64: =SUM(Part_Marks!J64:M64) -> 8 | K64: =SUM(Part_Marks!N64:Q64) -> 9.5 | L64: =IF(ISNUMBER(SEARCH("Q1",$G64)),0,H64) -> 8 | M64: =IF(ISNUMBER(SEARCH("Q2",$G64)),0,I64) -> 8.5 | N64: =IF(ISNUMBER(SEARCH("Q3",$G64)),0,J64) -> 8 | O64: =IF(ISNUMBER(SEARCH("Q4",$G64)),0,K64) -> 9.5 | P64: =LARGE(L64:O64,1)+LARGE(L64:O64,2)+LARGE(L64:O64,3) -> 26 | Q64: =COUNTIFS(Error_Log!$A:$A,$B64,Error_Log!$F:$F,"Error") -> 6 | R64: 14 | S64: All four attempted: Q3 (8.0) is the lowest and must be dropped. Style: verbose. | T64: 02_Answer_Sheets/ME5309_Midsem_S60_Ankita_Sinha.pdf | U64: 5
C66: Batch average (/30) | P66: =AVERAGE(P5:P64) -> 22.35
C67: Highest / lowest | P67: =MAX(P5:P64)&" / "&MIN(P5:P64) -> 30 / 7

Sheet Part_Marks
A1: Part-wise expected marks (ground truth) - ME 5309 Midsem, all 60 sheets
A2: Marks are what a careful examiner following the Rubric_ModelAnswer sheet would award (half-mark steps, error-carried-forward credit where noted). 0 = not attempted. Blue = hard-coded input.
A3: Roll No. | B3: Name | C3: Q1(a) | D3: Q1(b) | E3: Q1(c) | F3: Q2(a) | G3: Q2(b) | H3: Q2(c) | I3: Q2(d) | J3: Q3(a) | K3: Q3(b) | L3: Q3(c) | M3: Q3(d) | N3: Q4(a) | O3: Q4(b) | P3: Q4(c) | Q3: Q4(d)
A4: Max marks | C4: 4 | D4: 3 | E4: 3 | F4: 2 | G4: 2 | H4: 4 | I4: 2 | J4: 2 | K4: 2 | L4: 4 | M4: 2 | N4: 2 | O4: 2 | P4: 4 | Q4: 2
A5: ME25M001 | B5: Aarav Sharma | C5: 4 | D5: 3 | E5: 3 | F5: 2 | G5: 2 | H5: 4 | I5: 2 | J5: 2 | K5: 2 | L5: 4 | M5: 2 | N5: 0 | O5: 0 | P5: 0 | Q5: 0
A6: ME25M002 | B6: Diya Nair | C6: 0 | D6: 0 | E6: 0 | F6: 2 | G6: 2 | H6: 4 | I6: 2 | J6: 2 | K6: 1.5 | L6: 4 | M6: 2 | N6: 2 | O6: 2 | P6: 4 | Q6: 1.5
A7: ME25M003 | B7: Rohan Mehta | C7: 2 | D7: 2.5 | E7: 2 | F7: 1.5 | G7: 1 | H7: 2 | I7: 1 | J7: 0 | K7: 0 | L7: 0 | M7: 0 | N7: 2 | O7: 1 | P7: 3 | Q7: 1
A8: ME25M004 | B8: Ananya Iyer | C8: 2 | D8: 1.5 | E8: 0 | F8: 2 | G8: 1.5 | H8: 4 | I8: 1.5 | J8: 1 | K8: 1.5 | L8: 3 | M8: 1 | N8: 2 | O8: 1 | P8: 4 | Q8: 1
A9: ME25M005 | B9: Karthik Subramanian | C9: 0 | D9: 0 | E9: 3 | F9: 0 | G9: 0 | H9: 0 | I9: 0 | J9: 2 | K9: 0 | L9: 0 | M9: 2 | N9: 0 | O9: 0 | P9: 0 | Q9: 2
A10: ME25M006 | B10: Meera Krishnan | C10: 4 | D10: 3 | E10: 3 | F10: 1.5 | G10: 2 | H10: 2.5 | I10: 2 | J10: 2 | K10: 2 | L10: 4 | M10: 1 | N10: 2 | O10: 1 | P10: 3 | Q10: 1.5
A11: ME25M007 | B11: Vikram Patel | C11: 0 | D11: 0 | E11: 0 | F11: 1 | G11: 1 | H11: 0.5 | I11: 1 | J11: 0 | K11: 1 | L11: 1 | M11: 0 | N11: 0.5 | O11: 0 | P11: 1 | Q11: 1
A12: ME25M008 | B12: Sneha Reddy | C12: 4 | D12: 3 | E12: 2 | F12: 0 | G12: 0 | H12: 0 | I12: 0 | J12: 0 | K12: 0 | L12: 0 | M12: 0 | N12: 2 | O12: 1 | P12: 4 | Q12: 1.5
A13: ME25M009 | B13: Arjun Das | C13: 2 | D13: 3 | E13: 3 | F13: 2 | G13: 1.5 | H13: 2 | I13: 1 | J13: 1 | K13: 1 | L13: 2 | M13: 2 | N13: 0 | O13: 0 | P13: 0 | Q13: 0
A14: ME25M010 | B14: Priya Venkatesh | C14: 4 | D14: 2.5 | E14: 3 | F14: 2 | G14: 2 | H14: 4 | I14: 2 | J14: 2 | K14: 1 | L14: 4 | M14: 2 | N14: 2 | O14: 2 | P14: 4 | Q14: 2
A15: ME25M011 | B15: Rahul Gupta | C15: 3.5 | D15: 2.5 | E15: 3 | F15: 0 | G15: 0 | H15: 0 | I15: 0 | J15: 2 | K15: 1.5 | L15: 2 | M15: 1 | N15: 1 | O15: 1 | P15: 3 | Q15: 1.5
A16: ME25M012 | B16: Ishita Banerjee | C16: 0 | D16: 0 | E16: 0 | F16: 2 | G16: 2 | H16: 4 | I16: 1.5 | J16: 2 | K16: 2 | L16: 3 | M16: 2 | N16: 2 | O16: 1 | P16: 4 | Q16: 2
... A64: ME25M060 | B64: Ankita Sinha | C64: 3 | D64: 3 | E64: 2 | F64: 2 | G64: 2 | H64: 2.5 | I64: 2 | J64: 1 | K64: 2 | L64: 3 | M64: 2 | N64: 2 | O64: 2 | P64: 4 | Q64: 1.5

Sheet Error_Log
A1: Error log: what was deliberately done in each answer sheet and the marks it costs
A2: Row type: Error = deliberate mistake or omission; Alternative method = valid but unusual approach (no loss expected); Not attempted / Struck out = question-level rows. Marks awarded link to Part_Marks.
A3: Roll No. | B3: Name | C3: Question | D3: Part | E3: Variant id | F3: Row type | G3: Category | H3: What the student did | I3: Marks awarded | J3: Max | K3: Marks lost | L3: Counted in total?
A4: ME25M001 | B4: Aarav Sharma | C4: Q4 | D4: All | E4: n/a | F4: Not attempted | G4: Omission | H4: Question left blank (0 marks; may be dropped from best-3 anyway) | I4: 0 | J4: 10 | K4: =J4-I4 -> 10 | L4: n/a
A5: ME25M002 | B5: Diya Nair | C5: Q2 | D5: c | E5: ok_approx | F5: Alternative method | G5: Valid alternative | H5: Used the small-error estimate sin(theta_ss) ~ 1 giving 2.81 deg; acceptable because the question asks to estimate (full marks expected) | I5: =Part_Marks!H6 -> 4 | J5: 4 | K5: =J5-I5 -> 0 | L5: Yes
A6: ME25M002 | B6: Diya Nair | C6: Q3 | D6: b | E6: e4 | F6: Error | G6: Incomplete | H6: Coefficients correct but DC gain only asserted, not verified from the difference equation | I6: =Part_Marks!K6 -> 1.5 | J6: 2 | K6: =J6-I6 -> 0.5 | L6: Yes
A7: ME25M002 | B7: Diya Nair | C7: Q4 | D7: d | E7: e3 | F7: Error | G7: Weak remedy | H7: Zero-error derivation correct; windup named but remedy ("reduce K_I to zero") is not a standard anti-windup scheme | I7: =Part_Marks!Q6 -> 1.5 | J7: 2 | K7: =J7-I7 -> 0.5 | L7: Yes
A8: ME25M002 | B8: Diya Nair | C8: Q1 | D8: All | E8: n/a | F8: Not attempted | G8: Omission | H8: Question left blank (0 marks; may be dropped from best-3 anyway) | I8: 0 | J8: 10 | K8: =J8-I8 -> 10 | L8: n/a
A9: ME25M003 | B9: Rohan Mehta | C9: Q1 | D9: a | E9: e1 | F9: Error | G9: Unit conversion | H9: Unit slip: 16 mm / 5 µm evaluated as 16/5 = 3.2 (µm not converted); FOV and per-pixel values absurd but formulas right (error carried forward) | I9: =Part_Marks!C7 -> 2 | J9: 4 | K9: =J9-I9 -> 2 | L9: Yes
A10: ME25M003 | B10: Rohan Mehta | C10: Q1 | D10: b | E10: e2 | F10: Error | G10: Calculation | H10: Decimal-place slip in final division (0.0122 N instead of 0.122 N); method correct | I10: =Part_Marks!D7 -> 2.5 | J10: 3 | K10: =J10-I10 -> 0.5 | L10: Yes
A11: ME25M003 | B11: Rohan Mehta | C11: Q1 | D11: c | E11: e2 | F11: Error | G11: Calculation | H11: Integration slip: ∫e^(−2τ)dτ taken as 1−e^(−0.2) (missing 1/2): G = 0.1813 instead of 0.0906; F and formulas right | I11: =Part_Marks!E7 -> 2 | J11: 3 | K11: =J11-I11 -> 1 | L11: Yes
A12: ME25M003 | B12: Rohan Mehta | C12: Q2 | D12: a | E12: e2 | F12: Error | G12: Sign error | H12: Sign error on damping term in state equation (+b x2); equilibrium condition and range correct | I12: =Part_Marks!F7 -> 1.5 | J12: 2 | K12: =J12-I12 -> 0.5 | L12: Yes
A13: ME25M003 | B13: Rohan Mehta | C13: Q2 | D13: b | E13: e1 | F13: Error | G13: Calculation | H13: Calculator left in radian mode: cos(60) = -0.952 gives A21 = +116.8 instead of -61.31; structure, A22 and B right | I13: =Part_Marks!G7 -> 1 | J13: 2 | K13: =J13-I13 -> 1 | L13: Yes
A14: ME25M003 | B14: Rohan Mehta | C14: Q2 | D14: c | E14: e2 | F14: Error | G14: Unit conversion | H14: theta_d entered in degrees while Kp is in N.m/rad (unit inconsistency): error 0.049 deg instead of 2.81 deg; reasoning right | I14: =Part_Marks!H7 -> 2 | J14: 4 | K14: =J14-I14 -> 2 | L14: Yes
A15: ME25M003 | B15: Rohan Mehta | C15: Q2 | D15: d | E15: e1 | F15: Error | G15: Conceptual | H15: Error = 0 correct, but claims poles change (ignores cos 90 deg = 0) | I15: =Part_Marks!I7 -> 1 | J15: 2 | K15: =J15-I15 -> 1 | L15: Yes
A16: ME25M003 | B16: Rohan Mehta | C16: Q4 | D16: b | E16: e2 | F16: Error | G16: Calculation | H16: Correct DC-gain formula but denominator not updated for b=0.75 (used 8 not 7.5): result 0.75 / 25% instead of 0.8 / 20% | I16: =Part_Marks!O7 -> 1 | J16: 2 | K16: =J16-I16 -> 1 | L16: Yes
A17: ME25M003 | B17: Rohan Mehta | C17: Q4 | D17: c | E17: e3 | F17: Error | G17: Calculation | H17: Expansion slip: (s+4)(s^2+4s+8) taken as s^3+8s^2+16s+32 (should be 24s) giving k1=10 instead of 18 | I17: =Part_Marks!P7 -> 3 | J17: 4 | K17: =J17-I17 -> 1 | L17: Yes
A18: ME25M003 | B18: Rohan Mehta | C18: Q4 | D18: d | E18: e1 | F18: Error | G18: Conceptual | H18: Zero-error argument correct; failure mode given (noise amplification) is not the standard one (windup) | I18: =Part_Marks!Q7 -> 1 | J18: 2 | K18: =J18-I18 -> 1 | L18: Yes
A19: ME25M003 | B19: Rohan Mehta | C19: Q3 | D19: All | E19: n/a | F19: Not attempted | G19: Omission | H19: Question left blank (0 marks; may be dropped from best-3 anyway) | I19: 0 | J19: 10 | K19: =J19-I19 -> 10 | L19: n/a
A20: ME25M004 | B20: Ananya Iyer | C20: Q1 | D20: a | E20: e2 | F20: Error | G20: Conceptual | H20: Similar-triangle ratio inverted (f/Z instead of Z/f): FOV = 0.256 mm instead of 160 mm; f_x correct | I20: =Part_Marks!C8 -> 2 | J20: 4 | K20: =J20-I20 -> 2 | L20: Yes
A21: ME25M004 | B21: Ananya Iyer | C21: Q1 | D21: b | E21: e1 | F21: Error | G21: Incomplete | H21: Stopped at ADC LSB voltage; never converted to force via sensor sensitivity | I21: =Part_Marks!D8 -> 1.5 | J21: 3 | K21: =J21-I21 -> 1.5 | L21: Yes
A22: ME25M004 | B22: Ananya Iyer | C22: Q1 | D22: c | E22: e1 | F22: Error | G22: Method | H22: Used forward-Euler instead of the exact ZOH discretisation (F=0.8, G=0.1); question demands exact model | I22: =Part_Marks!E8 -> 0 | J22: 3 | K22: =J22-I22 -> 3 | L22: Yes
A23: ME25M004 | B23: Ananya Iyer | C23: Q2 | D23: b | E23: e3 | F23: Error | G23: Incomplete | H23: B given as [0;1], omitting the 1/J = 50 factor; A fully correct | I23: =Part_Marks!G8 -> 1.5 | J23: 2 | K23: =J23-I23 -> 0.5 | L23: Yes
A24: ME25M004 | B24: Ananya Iyer | C24: Q2 | D24: d | E24: e2 | F24: Error | G24: Weak justification | H24: Correct conclusions (error 0; poles unchanged) but justification wrong: term depends on theta; real reason is cos 90 deg = 0 | I24: =Part_Marks!I8 -> 1.5 | J24: 2 | K24: =J24-I24 -> 0.5 | L24: Yes
A25: ME25M004 | B25: Ananya Iyer | C25: Q3 | D25: a | E25: e1 | F25: Error | G25: Conceptual | H25: One valid reason (noise amplification); second reason (memory/processing cost) is wrong | I25: =Part_Marks!J8 -> 1 | J25: 2 | K25: =J25-I25 -> 1 | L25: No (struck out)
A26: ME25M004 | B26: Ananya Iyer | C26: Q3 | D26: b | E26: e2 | F26: Error | G26: Calculation | H26: Forgot 2*pi: used w_c = 20 rad/s instead of 125.66 rad/s; Tustin method and DC check correct | I26: =Part_Marks!K8 -> 1.5 | J26: 2 | K26: =J26-I26 -> 0.5 | L26: No (struck out)
A27: ME25M004 | B27: Ananya Iyer | C27: Q3 | D27: c | E27: e4 | F27: Error | G27: Calculation | H27: Arithmetic slip: l2 = 100 - 18 = 82 (forgot 2*l1 = 36) instead of 64; derivation and l1 correct | I27: =Part_Marks!L8 -> 3 | J27: 4 | K27: =J27-I27 -> 1 | L27: No (struck out)
A28: ME25M004 | B28: Ananya Iyer | C28: Q3 | D28: d | E28: e1 | F28: Error | G28: Conceptual | H28: Observer advantage correct (uses model/input, no lag); circumstance wrong (claims filter safer at high sampling rate) | I28: =Part_Marks!M8 -> 1 | J28: 2 | K28: =J28-I28 -> 1 | L28: No (struck out)
A29: ME25M004 | B29: Ananya Iyer | C29: Q4 | D29: b | E29: e3 | F29: Error | G29: Calculation | H29: theta_ss = 0.8 correct but % error computed as 80% (should be 20%) | I29: =Part_Marks!O8 -> 1 | J29: 2 | K29: =J29-I29 -> 1 | L29: Yes
A30: ME25M004 | B30: Ananya Iyer | C30: Q4 | D30: d | E30: e4 | F30: Error | G30: Weak justification | H30: Circular argument for zero error (stable so zero error); windup with clamping remedy correct | I30: =Part_Marks!Q8 -> 1 | J30: 2 | K30: =J30-I30 -> 1 | L30: Yes
A31: ME25M004 | B31: Ananya Iyer | C31: Q3 | D31: All | E31: n/a | F31: Struck out | G31: Strike-out | H31: Student crossed the whole answer out; it must not be counted even though it was attempted | I31: =SUM(Part_Marks!J8:M8) -> 6.5 | J31: 10 | K31: =J31-I31 -> 3.5 | L31: No (struck out)
A32: ME25M005 | B32: Karthik Subramanian | C32: Q1 | D32: a | E32: bare | F32: Error | G32: Missing working | H32: Final answers only; no formula or substitution (instruction 5 gives no credit) | I32: =Part_Marks!C9 -> 0 | J32: 4 | K32: =J32-I32 -> 4 | L32: Yes
A33: ME25M005 | B33: Karthik Subramanian | C33: Q1 | D33: b | E33: bare | F33: Error | G33: Missing working | H33: Bare numeric answer; no formula or substitution (no credit under instruction 5) | I33: =Part_Marks!D9 -> 0 | J33: 3 | K33: =J33-I33 -> 3 | L33: Yes
A34: ME25M005 | B34: Karthik Subramanian | C34: Q3 | D34: b | E34: bare | F34: Error | G34: Missing working | H34: Final difference equation and DC gain stated without derivation (no credit under instruction 5) | I34: =Part_Marks!K9 -> 0 | J34: 2 | K34: =J34-I34 -> 2 | L34: Yes
A35: ME25M005 | B35: Karthik Subramanian | C35: Q3 | D35: c | E35: bare | F35: Error | G35: Missing working | H35: Final L stated without derivation of the characteristic polynomial (no credit under instruction 5) | I35: =Part_Marks!L9 -> 0 | J35: 4 | K35: =J35-I35 -> 4 | L35: Yes
A36: ME25M005 | B36: Karthik Subramanian | C36: Q4 | D36: a | E36: bare | F36: Error | G36: Missing working | H36: Poles and N_ff stated without derivation (no credit under instruction 5) | I36: =Part_Marks!N9 -> 0 | J36: 2 | K36: =J36-I36 -> 2 | L36: Yes
A37: ME25M005 | B37: Karthik Subramanian | C37: Q4 | D37: b | E37: bare | F37: Error | G37: Missing working | H37: Answer stated without formula or substitution (no credit under instruction 5) | I37: =Part_Marks!O9 -> 0 | J37: 2 | K37: =J37-I37 -> 2 | L37: Yes
A38: ME25M005 | B38: Karthik Subramanian | C38: Q4 | D38: c | E38: bare | F38: Error | G38: Missing working | H38: Final gains stated without derivation (no credit under instruction 5) | I38: =Part_Marks!P9 -> 0 | J38: 4 | K38: =J38-I38 -> 4 | L38: Yes
A39: ME25M005 | B39: Karthik Subramanian | C39: Q2 | D39: All | E39: n/a | F39: Not attempted | G39: Omission | H39: Question left blank (0 marks; may be dropped from best-3 anyway) | I39: 0 | J39: 10 | K39: =J39-I39 -> 10 | L39: n/a
A40: ME25M006 | B40: Meera Krishnan | C40: Q2 | D40: a | E40: e1 | F40: Error | G40: Incomplete | H40: Equilibrium range given as 0 <= tau0 <= mgl; misses negative torques (should be |tau0| <= mgl) | I40: =Part_Marks!F10 -> 1.5 | J40: 2 | K40: =J40-I40 -> 0.5 | L40: Yes
...

Sheet Rubric_ModelAnswer
A1: Rubric and model answers used for the ground-truth marks
A2: Derived from the paper (no rubric was supplied): part marks as printed, split into items. Rules: error-carried-forward credit when method is right; bare answers without formula/substitution earn 0 (paper instruction 5); -0.5 for missing units or fewer than 3 s.f. (instructions 6-7).
A3: Part | B3: Max | C3: Rubric items (marks) | D3: Model answer
A4: Q1(a) | B4: 4 | C4: f_x = f/p = 3200 px (1.5); FOV by similar triangles = 160 mm (1.5); mm per pixel = 0.125 (1.0) | D4: f_x = 16 mm / 5 um = 3200 px. Sensor width 6.4 mm; FOV = 6.4*400/16 = 160 mm; 160/1280 = 0.125 mm/px (= Z/f_x).
A5: Q1(b) | B5: 3 | C5: LSB = 5/4096 = 1.22 mV (1.5); convert with 10 mV/N (1.0); units and assumption (0.5) | D5: LSB = 5/2^12 = 1.2207 mV; dF = 1.2207/10 = 0.122 N.
A6: Q1(c) | B6: 3 | C6: Formulas F = e^(AT), G = A^-1 (F-I) B (1.0); F value (1.0); G value (1.0) | D6: F = e^-0.2 = 0.8187; G = (1 - e^-0.2)/2 = 0.0906; x[k+1] = 0.8187 x[k] + 0.0906 u[k].
A7: Q2(a) | B7: 2 | C7: States and nonlinear model (1.0); equilibrium equation and |tau0| <= mgl (1.0) | D7: x1 = theta, x2 = theta-dot; x2-dot = (tau - b x2 - mgl sin x1)/J. Equilibrium: mgl sin(theta_e) = tau0, exists iff |tau0| <= mgl = 2.4525 N.m.
A8: Q2(b) | B8: 2 | C8: A with numerical entries (1.5); B (0.5) | D8: A = [0 1; -(mgl/J)cos60 -b/J] = [0 1; -61.31 -2.5]; B = [0; 1/J] = [0; 50].
A9: Q2(c) | B9: 4 | C9: Gravity must be balanced so no rest at theta_d (1.5); steady-state equation (1.0); numerical solution (1.5) | D9: Kp(theta_d - theta_ss) = mgl sin(theta_ss); 50(pi/2 - theta) = 2.4525 sin(theta) gives theta_ss = 87.19 deg, error = 2.81 deg (estimate mgl/Kp = 2.81 deg accepted).
A10: Q2(d) | B10: 2 | C10: Error = 0 (1.0); poles unchanged with justification (1.0) | D10: theta_ss = theta_d. Linearised stiffness was Kp + mgl cos(theta_d); cos 90 = 0 so poles are unchanged (true only because theta_d = 90 deg).
A11: Q3(a) | B11: 2 | C11: Two distinct valid reasons, 1.0 each | D11: (1) Differentiation amplifies (quantisation/measurement) noise; (2) encoder quantisation gives coarse velocity steps q/T; (also: delay/lag).
A12: Q3(b) | B12: 2 | C12: Tustin coefficients with method (1.5); DC gain verified (0.5) | D12: wc = 125.66 rad/s, a = wc T/2 = 0.06283; y[k] = 0.05912 (u[k]+u[k-1]) + 0.88177 y[k-1]; H(1) = 2a/((1+a)-(1-a)) = 1.
A13: Q3(c) | B13: 4 | C13: Characteristic polynomial (1.5); matching with s^2+20s+100 (1.0); L values (1.5) | D13: s^2 + (2+l1)s + (2 l1 + l2) = (s+10)^2 gives l1 = 18, l2 = 64.
A14: Q3(d) | B14: 2 | C14: Observer advantage (1.0); circumstance where filter is safer (1.0) | D14: Observer uses model and input: no phase lag, estimates unmeasured states/disturbances. Filter safer when model is uncertain or changing (payload, friction, contact, saturation).
A15: Q4(a) | B15: 2 | C15: Closed-loop poles (1.0); N_ff (1.0) | D15: s^2 + 4s + 8: poles -2 +/- 2j; DC gain N_ff/8 = 1 so N_ff = 8.
... A18: Q4(d) | B18: 2 | C18: Zero steady-state error argument (1.0); windup and anti-windup remedy (1.0) | D18: At steady state xi-dot = r - theta_ss = 0 independent of b, c. Failure mode: integrator windup with saturation; remedy: clamping / back-calculation anti-windup.
A19: Total | B19: =SUM(B4:B18) -> 40 | C19: 60 marks across four questions; the best three (30 marks) count
